Workbook

Sheet Data
A1: Name | B1: Date | D1: Model | E1: Objective | F1: N | G1: Instance | I1: Cuts | J1: Presolve | K1: Heuristics | L1: Runtime | N1: Value | O1: Bound | P1: MIP Gap | Q1: Sol Count | R1: Node Count
A2: NU-010-StripPacking-10-0 | B2: 45985 | D2: NU | E2: StripPacking | F2: 10 | G2: 0 | I2: 0 | J2: 1 | K2: 0 | L2: 0.241234 | N2: 39 | O2: 39 | P2: 0 | Q2: 10 | R2: 11360
A3: NU-111-StripPacking-10-0 | B3: 45985 | D3: NU | E3: StripPacking | F3: 10 | G3: 0 | I3: 1 | J3: 1 | K3: 1 | L3: 1.444574 | N3: 39 | O3: 39 | P3: 0 | Q3: 7 | R3: 5032
A4: NU-010-StripPacking-15-0 | B4: 45985 | D4: NU | E4: StripPacking | F4: 15 | G4: 0 | I4: 0 | J4: 1 | K4: 0 | L4: 500.71087 | N4: 45 | O4: 45 | P4: 0 | Q4: 10 | R4: 7150556
A5: NU-111-StripPacking-15-0 | B5: 45985 | D5: NU | E5: StripPacking | F5: 15 | G5: 0 | I5: 1 | J5: 1 | K5: 1 | L5: 412.46992 | N5: 45 | O5: 45 | P5: 0 | Q5: 10 | R5: 67594
A6: NU-010-StripPacking-20-0 | B6: 45985 | D6: NU | E6: StripPacking | F6: 20 | G6: 0 | I6: 0 | J6: 1 | K6: 0 | L6: 3601.1319 | N6: 79 | O6: 48 | P6: 0.392405 | Q6: 10 | R6: 32083773
A7: NU-111-StripPacking-20-0 | B7: 45985 | D7: NU | E7: StripPacking | F7: 20 | G7: 0 | I7: 1 | J7: 1 | K7: 1 | L7: 3600.0859 | N7: 78 | O7: 46 | P7: 0.410256 | Q7: 10 | R7: 808481
A8: NU-010-StripPacking-25-0 | B8: 45986 | D8: NU | E8: StripPacking | F8: 25 | G8: 0 | I8: 0 | J8: 1 | K8: 0 | L8: 3600.0942 | N8: 71 | O8: 36 | P8: 0.492958 | Q8: 10 | R8: 35882668
A9: NU-111-StripPacking-25-0 | B9: 45986 | D9: NU | E9: StripPacking | F9: 25 | G9: 0 | I9: 1 | J9: 1 | K9: 1 | L9: 3600.081 | N9: 70 | O9: 34 | P9: 0.514286 | Q9: 10 | R9: 711561
A10: NU-010-StripPacking-35-0 | B10: 45986 | D10: NU | E10: StripPacking | F10: 35 | G10: 0 | I10: 0 | J10: 1 | K10: 0 | L10: 3600.1235 | N10: 96 | O10: 48 | P10: 0.5 | Q10: 10 | R10: 22185595
A11: NU-111-StripPacking-35-0 | B11: 45986 | D11: NU | E11: StripPacking | F11: 35 | G11: 0 | I11: 1 | J11: 1 | K11: 1 | L11: 3600.3245 | N11: 94 | O11: 48 | P11: 0.489362 | Q11: 10 | R11: 367208
A12: NU-010-StripPacking-50-0 | B12: 45987 | D12: NU | E12: StripPacking | F12: 50 | G12: 0 | I12: 0 | J12: 1 | K12: 0 | L12: 3600.7901 | N12: 164 | O12: 39 | P12: 0.762195 | Q12: 10 | R12: 12065498
A13: NU-111-StripPacking-50-0 | B13: 45987 | D13: NU | E13: StripPacking | F13: 50 | G13: 0 | I13: 1 | J13: 1 | K13: 1 | L13: 3600.0991 | N13: 153 | O13: 37.485207 | P13: 0.754999 | Q13: 10 | R13: 72057
... A78: SBM-111-StripPacking-50-0 | B78: 45987 | D78: SBM | E78: StripPacking | F78: 50 | G78: 0 | I78: 1 | J78: 1 | K78: 1 | L78: 3600.0689 | N78: 152 | O78: 35.430981 | P78: 0.766901 | Q78: 10 | R78: 53486

Sheet Tables
C1: Time/Gap
C2: NU | D2: SU | E2: RU | F2: HU | G2: SB-L | H2: SB-M
C3: =IF(Data!L2<3600,IF(Data!L2<120,TEXT(Data!L2,"0.00")&"s",TEXT(Data!L2,"0")&"s"),TEXT(Data!P2*100,"0")&"%") -> 0.24s | D3: =IF(Data!L15<3600,IF(Data!L15<120,TEXT(Data!L15,"0.00")&"s",TEXT(Data!L15,"0")&"s"),TEXT(Data!P15*100,"0")&"%") -> 0.79s | E3: =IF(Data!L28<3600,IF(Data!L28<120,TEXT(Data!L28,"0.00")&"s",TEXT(Data!L28,"0")&"s"),TEXT(Data!P28*100,"0")&"%") -> 0.86s | F3: =IF(Data!L41<3600,IF(Data!L41<120,TEXT(Data!L41,"0.00")&"s",TEXT(Data!L41,"0")&"s"),TEXT(Data!P41*100,"0")&"%") -> 0.36s | G3: =IF(Data!L54<3600,IF(Data!L54<120,TEXT(Data!L54,"0.00")&"s",TEXT(Data!L54,"0")&"s"),TEXT(Data!P54*100,"0")&"%") -> 0.32s | H3: =IF(Data!L67<3600,IF(Data!L67<120,TEXT(Data!L67,"0.00")&"s",TEXT(Data!L67,"0")&"s"),TEXT(Data!P67*100,"0")&"%") -> 0.88s
C4: =IF(Data!L3<3600,IF(Data!L3<120,TEXT(Data!L3,"0.00")&"s",TEXT(Data!L3,"0")&"s"),TEXT(Data!P3*100,"0")&"%") -> 1.44s | D4: =IF(Data!L16<3600,IF(Data!L16<120,TEXT(Data!L16,"0.00")&"s",TEXT(Data!L16,"0")&"s"),TEXT(Data!P16*100,"0")&"%") -> 1.87s | E4: =IF(Data!L29<3600,IF(Data!L29<120,TEXT(Data!L29,"0.00")&"s",TEXT(Data!L29,"0")&"s"),TEXT(Data!P29*100,"0")&"%") -> 2.94s | F4: =IF(Data!L42<3600,IF(Data!L42<120,TEXT(Data!L42,"0.00")&"s",TEXT(Data!L42,"0")&"s"),TEXT(Data!P42*100,"0")&"%") -> 6.46s | G4: =IF(Data!L55<3600,IF(Data!L55<120,TEXT(Data!L55,"0.00")&"s",TEXT(Data!L55,"0")&"s"),TEXT(Data!P55*100,"0")&"%") -> 10.93s | H4: =IF(Data!L68<3600,IF(Data!L68<120,TEXT(Data!L68,"0.00")&"s",TEXT(Data!L68,"0")&"s"),TEXT(Data!P68*100,"0")&"%") -> 20.62s
C5: =IF(Data!L4<3600,IF(Data!L4<120,TEXT(Data!L4,"0.00")&"s",TEXT(Data!L4,"0")&"s"),TEXT(Data!P4*100,"0")&"%") -> 501s | D5: =IF(Data!L17<3600,IF(Data!L17<120,TEXT(Data!L17,"0.00")&"s",TEXT(Data!L17,"0")&"s"),TEXT(Data!P17*100,"0")&"%") -> 188s | E5: =IF(Data!L30<3600,IF(Data!L30<120,TEXT(Data!L30,"0.00")&"s",TEXT(Data!L30,"0")&"s"),TEXT(Data!P30*100,"0")&"%") -> 32.98s | F5: =IF(Data!L43<3600,IF(Data!L43<120,TEXT(Data!L43,"0.00")&"s",TEXT(Data!L43,"0")&"s"),TEXT(Data!P43*100,"0")&"%") -> 140s | G5: =IF(Data!L56<3600,IF(Data!L56<120,TEXT(Data!L56,"0.00")&"s",TEXT(Data!L56,"0")&"s"),TEXT(Data!P56*100,"0")&"%") -> 160s | H5: =IF(Data!L69<3600,IF(Data!L69<120,TEXT(Data!L69,"0.00")&"s",TEXT(Data!L69,"0")&"s"),TEXT(Data!P69*100,"0")&"%") -> 2215s
C6: =IF(Data!L5<3600,IF(Data!L5<120,TEXT(Data!L5,"0.00")&"s",TEXT(Data!L5,"0")&"s"),TEXT(Data!P5*100,"0")&"%") -> 412s | D6: =IF(Data!L18<3600,IF(Data!L18<120,TEXT(Data!L18,"0.00")&"s",TEXT(Data!L18,"0")&"s"),TEXT(Data!P18*100,"0")&"%") -> 452s | E6: =IF(Data!L31<3600,IF(Data!L31<120,TEXT(Data!L31,"0.00")&"s",TEXT(Data!L31,"0")&"s"),TEXT(Data!P31*100,"0")&"%") -> 188s | F6: =IF(Data!L44<3600,IF(Data!L44<120,TEXT(Data!L44,"0.00")&"s",TEXT(Data!L44,"0")&"s"),TEXT(Data!P44*100,"0")&"%") -> 443s | G6: =IF(Data!L57<3600,IF(Data!L57<120,TEXT(Data!L57,"0.00")&"s",TEXT(Data!L57,"0")&"s"),TEXT(Data!P57*100,"0")&"%") -> 1002s | H6: =IF(Data!L70<3600,IF(Data!L70<120,TEXT(Data!L70,"0.00")&"s",TEXT(Data!L70,"0")&"s"),TEXT(Data!P70*100,"0")&"%") -> 1856s
C7: =IF(Data!L6<3600,IF(Data!L6<120,TEXT(Data!L6,"0.00")&"s",TEXT(Data!L6,"0")&"s"),TEXT(Data!P6*100,"0")&"%") -> 39% | D7: =IF(Data!L19<3600,IF(Data!L19<120,TEXT(Data!L19,"0.00")&"s",TEXT(Data!L19,"0")&"s"),TEXT(Data!P19*100,"0")&"%") -> 35% | E7: =IF(Data!L32<3600,IF(Data!L32<120,TEXT(Data!L32,"0.00")&"s",TEXT(Data!L32,"0")&"s"),TEXT(Data!P32*100,"0")&"%") -> 37% | F7: =IF(Data!L45<3600,IF(Data!L45<120,TEXT(Data!L45,"0.00")&"s",TEXT(Data!L45,"0")&"s"),TEXT(Data!P45*100,"0")&"%") -> 38% | G7: =IF(Data!L58<3600,IF(Data!L58<120,TEXT(Data!L58,"0.00")&"s",TEXT(Data!L58,"0")&"s"),TEXT(Data!P58*100,"0")&"%") -> 37% | H7: =IF(Data!L71<3600,IF(Data!L71<120,TEXT(Data!L71,"0.00")&"s",TEXT(Data!L71,"0")&"s"),TEXT(Data!P71*100,"0")&"%") -> 44%
C8: =IF(Data!L7<3600,IF(Data!L7<120,TEXT(Data!L7,"0.00")&"s",TEXT(Data!L7,"0")&"s"),TEXT(Data!P7*100,"0")&"%") -> 41% | D8: =IF(Data!L20<3600,IF(Data!L20<120,TEXT(Data!L20,"0.00")&"s",TEXT(Data!L20,"0")&"s"),TEXT(Data!P20*100,"0")&"%") -> 40% | E8: =IF(Data!L33<3600,IF(Data!L33<120,TEXT(Data!L33,"0.00")&"s",TEXT(Data!L33,"0")&"s"),TEXT(Data!P33*100,"0")&"%") -> 43% | F8: =IF(Data!L46<3600,IF(Data!L46<120,TEXT(Data!L46,"0.00")&"s",TEXT(Data!L46,"0")&"s"),TEXT(Data!P46*100,"0")&"%") -> 38% | G8: =IF(Data!L59<3600,IF(Data!L59<120,TEXT(Data!L59,"0.00")&"s",TEXT(Data!L59,"0")&"s"),TEXT(Data!P59*100,"0")&"%") -> 42% | H8: =IF(Data!L72<3600,IF(Data!L72<120,TEXT(Data!L72,"0.00")&"s",TEXT(Data!L72,"0")&"s"),TEXT(Data!P72*100,"0")&"%") -> 49%
C9: =IF(Data!L8<3600,IF(Data!L8<120,TEXT(Data!L8,"0.00")&"s",TEXT(Data!L8,"0")&"s"),TEXT(Data!P8*100,"0")&"%") -> 49% | D9: =IF(Data!L21<3600,IF(Data!L21<120,TEXT(Data!L21,"0.00")&"s",TEXT(Data!L21,"0")&"s"),TEXT(Data!P21*100,"0")&"%") -> 49% | E9: =IF(Data!L34<3600,IF(Data!L34<120,TEXT(Data!L34,"0.00")&"s",TEXT(Data!L34,"0")&"s"),TEXT(Data!P34*100,"0")&"%") -> 52% | F9: =IF(Data!L47<3600,IF(Data!L47<120,TEXT(Data!L47,"0.00")&"s",TEXT(Data!L47,"0")&"s"),TEXT(Data!P47*100,"0")&"%") -> 51% | G9: =IF(Data!L60<3600,IF(Data!L60<120,TEXT(Data!L60,"0.00")&"s",TEXT(Data!L60,"0")&"s"),TEXT(Data!P60*100,"0")&"%") -> 53% | H9: =IF(Data!L73<3600,IF(Data!L73<120,TEXT(Data!L73,"0.00")&"s",TEXT(Data!L73,"0")&"s"),TEXT(Data!P73*100,"0")&"%") -> 53%
C10: =IF(Data!L9<3600,IF(Data!L9<120,TEXT(Data!L9,"0.00")&"s",TEXT(Data!L9,"0")&"s"),TEXT(Data!P9*100,"0")&"%") -> 51% | D10: =IF(Data!L22<3600,IF(Data!L22<120,TEXT(Data!L22,"0.00")&"s",TEXT(Data!L22,"0")&"s"),TEXT(Data!P22*100,"0")&"%") -> 51% | E10: =IF(Data!L35<3600,IF(Data!L35<120,TEXT(Data!L35,"0.00")&"s",TEXT(Data!L35,"0")&"s"),TEXT(Data!P35*100,"0")&"%") -> 52% | F10: =IF(Data!L48<3600,IF(Data!L48<120,TEXT(Data!L48,"0.00")&"s",TEXT(Data!L48,"0")&"s"),TEXT(Data!P48*100,"0")&"%") -> 51% | G10: =IF(Data!L61<3600,IF(Data!L61<120,TEXT(Data!L61,"0.00")&"s",TEXT(Data!L61,"0")&"s"),TEXT(Data!P61*100,"0")&"%") -> 50% | H10: =IF(Data!L74<3600,IF(Data!L74<120,TEXT(Data!L74,"0.00")&"s",TEXT(Data!L74,"0")&"s"),TEXT(Data!P74*100,"0")&"%") -> 51%
C11: =IF(Data!L10<3600,IF(Data!L10<120,TEXT(Data!L10,"0.00")&"s",TEXT(Data!L10,"0")&"s"),TEXT(Data!P10*100,"0")&"%") -> 50% | D11: =IF(Data!L23<3600,IF(Data!L23<120,TEXT(Data!L23,"0.00")&"s",TEXT(Data!L23,"0")&"s"),TEXT(Data!P23*100,"0")&"%") -> 50% | E11: =IF(Data!L36<3600,IF(Data!L36<120,TEXT(Data!L36,"0.00")&"s",TEXT(Data!L36,"0")&"s"),TEXT(Data!P36*100,"0")&"%") -> 53% | F11: =IF(Data!L49<3600,IF(Data!L49<120,TEXT(Data!L49,"0.00")&"s",TEXT(Data!L49,"0")&"s"),TEXT(Data!P49*100,"0")&"%") -> 50% | G11: =IF(Data!L62<3600,IF(Data!L62<120,TEXT(Data!L62,"0.00")&"s",TEXT(Data!L62,"0")&"s"),TEXT(Data!P62*100,"0")&"%") -> 52% | H11: =IF(Data!L75<3600,IF(Data!L75<120,TEXT(Data!L75,"0.00")&"s",TEXT(Data!L75,"0")&"s"),TEXT(Data!P75*100,"0")&"%") -> 52%
C12: =IF(Data!L11<3600,IF(Data!L11<120,TEXT(Data!L11,"0.00")&"s",TEXT(Data!L11,"0")&"s"),TEXT(Data!P11*100,"0")&"%") -> 49% | D12: =IF(Data!L24<3600,IF(Data!L24<120,TEXT(Data!L24,"0.00")&"s",TEXT(Data!L24,"0")&"s"),TEXT(Data!P24*100,"0")&"%") -> 48% | E12: =IF(Data!L37<3600,IF(Data!L37<120,TEXT(Data!L37,"0.00")&"s",TEXT(Data!L37,"0")&"s"),TEXT(Data!P37*100,"0")&"%") -> 51% | F12: =IF(Data!L50<3600,IF(Data!L50<120,TEXT(Data!L50,"0.00")&"s",TEXT(Data!L50,"0")&"s"),TEXT(Data!P50*100,"0")&"%") -> 49% | G12: =IF(Data!L63<3600,IF(Data!L63<120,TEXT(Data!L63,"0.00")&"s",TEXT(Data!L63,"0")&"s"),TEXT(Data!P63*100,"0")&"%") -> 48% | H12: =IF(Data!L76<3600,IF(Data!L76<120,TEXT(Data!L76,"0.00")&"s",TEXT(Data!L76,"0")&"s"),TEXT(Data!P76*100,"0")&"%") -> 48%
C13: =IF(Data!L12<3600,IF(Data!L12<120,TEXT(Data!L12,"0.00")&"s",TEXT(Data!L12,"0")&"s"),TEXT(Data!P12*100,"0")&"%") -> 76% | D13: =IF(Data!L25<3600,IF(Data!L25<120,TEXT(Data!L25,"0.00")&"s",TEXT(Data!L25,"0")&"s"),TEXT(Data!P25*100,"0")&"%") -> 72% | E13: =IF(Data!L38<3600,IF(Data!L38<120,TEXT(Data!L38,"0.00")&"s",TEXT(Data!L38,"0")&"s"),TEXT(Data!P38*100,"0")&"%") -> 82% | F13: =IF(Data!L51<3600,IF(Data!L51<120,TEXT(Data!L51,"0.00")&"s",TEXT(Data!L51,"0")&"s"),TEXT(Data!P51*100,"0")&"%") -> 79% | G13: =IF(Data!L64<3600,IF(Data!L64<120,TEXT(Data!L64,"0.00")&"s",TEXT(Data!L64,"0")&"s"),TEXT(Data!P64*100,"0")&"%") -> 70% | H13: =IF(Data!L77<3600,IF(Data!L77<120,TEXT(Data!L77,"0.00")&"s",TEXT(Data!L77,"0")&"s"),TEXT(Data!P77*100,"0")&"%") -> 76%
C14: =IF(Data!L13<3600,IF(Data!L13<120,TEXT(Data!L13,"0.00")&"s",TEXT(Data!L13,"0")&"s"),TEXT(Data!P13*100,"0")&"%") -> 75% | D14: =IF(Data!L26<3600,IF(Data!L26<120,TEXT(Data!L26,"0.00")&"s",TEXT(Data!L26,"0")&"s"),TEXT(Data!P26*100,"0")&"%") -> 72% | E14: =IF(Data!L39<3600,IF(Data!L39<120,TEXT(Data!L39,"0.00")&"s",TEXT(Data!L39,"0")&"s"),TEXT(Data!P39*100,"0")&"%") -> 74% | F14: =IF(Data!L52<3600,IF(Data!L52<120,TEXT(Data!L52,"0.00")&"s",TEXT(Data!L52,"0")&"s"),TEXT(Data!P52*100,"0")&"%") -> 75% | G14: =IF(Data!L65<3600,IF(Data!L65<120,TEXT(Data!L65,"0.00")&"s",TEXT(Data!L65,"0")&"s"),TEXT(Data!P65*100,"0")&"%") -> 77% | H14: =IF(Data!L78<3600,IF(Data!L78<120,TEXT(Data!L78,"0.00")&"s",TEXT(Data!L78,"0")&"s"),TEXT(Data!P78*100,"0")&"%") -> 77%
C16: Value
C17: 39 | D17: 39 | E17: 39 | F17: 39 | G17: 39 | H17: 39
C18: 39 | D18: 39 | E18: 39 | F18: 39 | G18: 39 | H18: 39
C19: 45 | D19: 45 | E19: 45 | F19: 45 | G19: 45 | H19: 45
C20: 45 | D20: 45 | E20: 45 | F20: 45 | G20: 45 | H20: 45
C21: 79 | D21: 77 | E21: 78 | F21: 77 | G21: 79 | H21: 81
C22: 78 | D22: 77 | E22: 80 | F22: 78 | G22: 79 | H22: 80
C23: 71 | D23: 71 | E23: 71 | F23: 70 | G23: 72 | H23: 72
C24: 70 | D24: 70 | E24: 71 | F24: 70 | G24: 68 | H24: 69
C25: 96 | D25: 96 | E25: 102 | F25: 96 | G25: 99 | H25: 99
C26: 94 | D26: 93 | E26: 97 | F26: 95 | G26: 92 | H26: 93
C27: 164 | D27: 168 | E27: 190 | F27: 163 | G27: 171 | H27: 173
C28: 153 | D28: 151 | E28: 155 | F28: 160 | G28: 156 | H28: 152
C30: Bound
C31: 39 | D31: 39 | E31: 39 | F31: 39 | G31: 39 | H31: 39
C32: 39 | D32: 39 | E32: 39 | F32: 39 | G32: 39 | H32: 39
C33: 45 | D33: 45 | E33: 45 | F33: 45 | G33: 45 | H33: 45
C34: 45 | D34: 45 | E34: 45 | F34: 45 | G34: 45 | H34: 45
C35: 48 | D35: 50 | E35: 49 | F35: 48 | G35: 50 | H35: 45
C36: 46 | D36: 46 | E36: 46 | F36: 48 | G36: 46 | H36: 41
C37: 36 | D37: 36 | E37: 34 | F37: 34 | G37: 34 | H37: 34
C38: 34 | D38: 34 | E38: 34 | F38: 34 | G38: 34 | H38: 34
C39: 48 | D39: 48 | E39: 48 | F39: 48 | G39: 48 | H39: 48
C40: 48 | D40: 48 | E40: 48 | F40: 48 | G40: 48 | H40: 48
C41: 39 | D41: 47 | E41: 35 | F41: 35 | G41: 51 | H41: 42
C42: 37.485207 | D42: 41.708769 | E42: 40.028584 | F42: 40 | G42: 36.125442 | H42: 35.430981
...
