Workbook

Sheet Data
A1: Name | B1: Date | D1: Model | E1: Objective | F1: N | G1: Instance | I1: Cuts | J1: Presolve | K1: Heuristics | L1: Runtime | N1: Value | O1: Bound | P1: MIP Gap | Q1: Sol Count | R1: Node Count
A2: NUspb-010-StripPacking-10-0 | B2: 45987 | D2: NUspb | E2: StripPacking | F2: 10 | G2: 0 | I2: 0 | J2: 1 | K2: 0 | L2: 0.287603 | N2: 39 | O2: 39 | P2: 0 | Q2: 7 | R2: 3843
A3: NUspb-111-StripPacking-10-0 | B3: 45987 | D3: NUspb | E3: StripPacking | F3: 10 | G3: 0 | I3: 1 | J3: 1 | K3: 1 | L3: 4.538375 | N3: 39 | O3: 39 | P3: 0 | Q3: 8 | R3: 6767
A4: NUspb-010-StripPacking-15-0 | B4: 45987 | D4: NUspb | E4: StripPacking | F4: 15 | G4: 0 | I4: 0 | J4: 1 | K4: 0 | L4: 102.09389 | N4: 45 | O4: 45 | P4: 0 | Q4: 10 | R4: 65175
A5: NUspb-111-StripPacking-15-0 | B5: 45987 | D5: NUspb | E5: StripPacking | F5: 15 | G5: 0 | I5: 1 | J5: 1 | K5: 1 | L5: 304.16454 | N5: 45 | O5: 45 | P5: 0 | Q5: 10 | R5: 22317
A6: NUspb-010-StripPacking-20-0 | B6: 45987 | D6: NUspb | E6: StripPacking | F6: 20 | G6: 0 | I6: 0 | J6: 1 | K6: 0 | L6: 3600.0514 | N6: 76 | O6: 50 | P6: 0.342105 | Q6: 10 | R6: 750990
A7: NUspb-111-StripPacking-20-0 | B7: 45987 | D7: NUspb | E7: StripPacking | F7: 20 | G7: 0 | I7: 1 | J7: 1 | K7: 1 | L7: 3600.0854 | N7: 77 | O7: 48 | P7: 0.376623 | Q7: 10 | R7: 56923
A8: NUspb-010-StripPacking-25-0 | B8: 45987 | D8: NUspb | E8: StripPacking | F8: 25 | G8: 0 | I8: 0 | J8: 1 | K8: 0 | L8: 3600.0606 | N8: 70 | O8: 34 | P8: 0.514286 | Q8: 10 | R8: 800551
A9: NUspb-111-StripPacking-25-0 | B9: 45987 | D9: NUspb | E9: StripPacking | F9: 25 | G9: 0 | I9: 1 | J9: 1 | K9: 1 | L9: 3600.1502 | N9: 70 | O9: 34 | P9: 0.514286 | Q9: 10 | R9: 123816
A10: NUspb-010-StripPacking-35-0 | B10: 45987 | D10: NUspb | E10: StripPacking | F10: 35 | G10: 0 | I10: 0 | J10: 1 | K10: 0 | L10: 3600.1351 | N10: 93 | O10: 48 | P10: 0.483871 | Q10: 10 | R10: 226351
A11: NUspb-111-StripPacking-35-0 | B11: 45987 | D11: NUspb | E11: StripPacking | F11: 35 | G11: 0 | I11: 1 | J11: 1 | K11: 1 | L11: 3600.1166 | N11: 92 | O11: 48 | P11: 0.478261 | Q11: 10 | R11: 13790
A12: NUspb-010-StripPacking-50-0 | B12: 45987 | D12: NUspb | E12: StripPacking | F12: 50 | G12: 0 | I12: 0 | J12: 1 | K12: 0 | L12: 3600.2012 | N12: 180 | O12: 35 | P12: 0.805556 | Q12: 5 | R12: 13561
A13: NUspb-111-StripPacking-50-0 | B13: 45987 | D13: NUspb | E13: StripPacking | F13: 50 | G13: 0 | I13: 1 | J13: 1 | K13: 1 | L13: 3600.3071 | N13: 145 | O13: 40 | P13: 0.724138 | Q13: 10 | R13: 399
... A78: SBspbM-111-StripPacking-50-0 | B78: 46002 | D78: SBspbM | E78: StripPacking | F78: 50 | G78: 0 | I78: 1 | J78: 1 | K78: 1 | L78: 3600.0549 | N78: 150 | O78: 35 | P78: 0.766667 | Q78: 10 | R78: 867

Sheet Sheet1
C1: Time/Gap
C2: NU | D2: SU | E2: RU | F2: HU | G2: SB-L | H2: SB-M
C3: =IF(Data!L2<3600,IF(Data!L2<120,TEXT(Data!L2,"0.00")&"s",TEXT(Data!L2,"0")&"s"),TEXT(Data!P2*100,"0")&"%") -> 0.29s | D3: =IF(Data!L15<3600,IF(Data!L15<120,TEXT(Data!L15,"0.00")&"s",TEXT(Data!L15,"0")&"s"),TEXT(Data!P15*100,"0")&"%") -> 1.15s | E3: =IF(Data!L28<3600,IF(Data!L28<120,TEXT(Data!L28,"0.00")&"s",TEXT(Data!L28,"0")&"s"),TEXT(Data!P28*100,"0")&"%") -> 0.67s | F3: =IF(Data!L41<3600,IF(Data!L41<120,TEXT(Data!L41,"0.00")&"s",TEXT(Data!L41,"0")&"s"),TEXT(Data!P41*100,"0")&"%") -> 0.66s | G3: =IF(Data!L54<3600,IF(Data!L54<120,TEXT(Data!L54,"0.00")&"s",TEXT(Data!L54,"0")&"s"),TEXT(Data!P54*100,"0")&"%") -> 0.57s | H3: =IF(Data!L67<3600,IF(Data!L67<120,TEXT(Data!L67,"0.00")&"s",TEXT(Data!L67,"0")&"s"),TEXT(Data!P67*100,"0")&"%") -> 0.39s
C4: =IF(Data!L3<3600,IF(Data!L3<100,TEXT(Data!L3,"0.00")&"s",TEXT(Data!L3,"0")&"s"),TEXT(Data!P3*100,"0")&"%") -> 4.54s | D4: =IF(Data!L16<3600,IF(Data!L16<120,TEXT(Data!L16,"0.00")&"s",TEXT(Data!L16,"0")&"s"),TEXT(Data!P16*100,"0")&"%") -> 2.24s | E4: =IF(Data!L29<3600,IF(Data!L29<120,TEXT(Data!L29,"0.00")&"s",TEXT(Data!L29,"0")&"s"),TEXT(Data!P29*100,"0")&"%") -> 6.96s | F4: =IF(Data!L42<3600,IF(Data!L42<120,TEXT(Data!L42,"0.00")&"s",TEXT(Data!L42,"0")&"s"),TEXT(Data!P42*100,"0")&"%") -> 3.69s | G4: =IF(Data!L55<3600,IF(Data!L55<120,TEXT(Data!L55,"0.00")&"s",TEXT(Data!L55,"0")&"s"),TEXT(Data!P55*100,"0")&"%") -> 2.68s | H4: =IF(Data!L68<3600,IF(Data!L68<120,TEXT(Data!L68,"0.00")&"s",TEXT(Data!L68,"0")&"s"),TEXT(Data!P68*100,"0")&"%") -> 3.93s
C5: =IF(Data!L4<3600,IF(Data!L4<100,TEXT(Data!L4,"0.00")&"s",TEXT(Data!L4,"0")&"s"),TEXT(Data!P4*100,"0")&"%") -> 102s | D5: =IF(Data!L17<3600,IF(Data!L17<120,TEXT(Data!L17,"0.00")&"s",TEXT(Data!L17,"0")&"s"),TEXT(Data!P17*100,"0")&"%") -> 237s | E5: =IF(Data!L30<3600,IF(Data!L30<120,TEXT(Data!L30,"0.00")&"s",TEXT(Data!L30,"0")&"s"),TEXT(Data!P30*100,"0")&"%") -> 61.02s | F5: =IF(Data!L43<3600,IF(Data!L43<120,TEXT(Data!L43,"0.00")&"s",TEXT(Data!L43,"0")&"s"),TEXT(Data!P43*100,"0")&"%") -> 167s | G5: =IF(Data!L56<3600,IF(Data!L56<120,TEXT(Data!L56,"0.00")&"s",TEXT(Data!L56,"0")&"s"),TEXT(Data!P56*100,"0")&"%") -> 54.30s | H5: =IF(Data!L69<3600,IF(Data!L69<120,TEXT(Data!L69,"0.00")&"s",TEXT(Data!L69,"0")&"s"),TEXT(Data!P69*100,"0")&"%") -> 121s
C6: =IF(Data!L5<3600,IF(Data!L5<120,TEXT(Data!L5,"0.00")&"s",TEXT(Data!L5,"0")&"s"),TEXT(Data!P5*100,"0")&"%") -> 304s | D6: =IF(Data!L18<3600,IF(Data!L18<120,TEXT(Data!L18,"0.00")&"s",TEXT(Data!L18,"0")&"s"),TEXT(Data!P18*100,"0")&"%") -> 739s | E6: =IF(Data!L31<3600,IF(Data!L31<120,TEXT(Data!L31,"0.00")&"s",TEXT(Data!L31,"0")&"s"),TEXT(Data!P31*100,"0")&"%") -> 356s | F6: =IF(Data!L44<3600,IF(Data!L44<120,TEXT(Data!L44,"0.00")&"s",TEXT(Data!L44,"0")&"s"),TEXT(Data!P44*100,"0")&"%") -> 295s | G6: =IF(Data!L57<3600,IF(Data!L57<120,TEXT(Data!L57,"0.00")&"s",TEXT(Data!L57,"0")&"s"),TEXT(Data!P57*100,"0")&"%") -> 155s | H6: =IF(Data!L70<3600,IF(Data!L70<120,TEXT(Data!L70,"0.00")&"s",TEXT(Data!L70,"0")&"s"),TEXT(Data!P70*100,"0")&"%") -> 248s
C7: =IF(Data!L6<3600,IF(Data!L6<120,TEXT(Data!L6,"0.00")&"s",TEXT(Data!L6,"0")&"s"),TEXT(Data!P6*100,"0")&"%") -> 34% | D7: =IF(Data!L19<3600,IF(Data!L19<120,TEXT(Data!L19,"0.00")&"s",TEXT(Data!L19,"0")&"s"),TEXT(Data!P19*100,"0")&"%") -> 36% | E7: =IF(Data!L32<3600,IF(Data!L32<120,TEXT(Data!L32,"0.00")&"s",TEXT(Data!L32,"0")&"s"),TEXT(Data!P32*100,"0")&"%") -> 38% | F7: =IF(Data!L45<3600,IF(Data!L45<120,TEXT(Data!L45,"0.00")&"s",TEXT(Data!L45,"0")&"s"),TEXT(Data!P45*100,"0")&"%") -> 41% | G7: =IF(Data!L58<3600,IF(Data!L58<120,TEXT(Data!L58,"0.00")&"s",TEXT(Data!L58,"0")&"s"),TEXT(Data!P58*100,"0")&"%") -> 31% | H7: =IF(Data!L71<3600,IF(Data!L71<120,TEXT(Data!L71,"0.00")&"s",TEXT(Data!L71,"0")&"s"),TEXT(Data!P71*100,"0")&"%") -> 32%
C8: =IF(Data!L7<3600,IF(Data!L7<120,TEXT(Data!L7,"0.00")&"s",TEXT(Data!L7,"0")&"s"),TEXT(Data!P7*100,"0")&"%") -> 38% | D8: =IF(Data!L20<3600,IF(Data!L20<120,TEXT(Data!L20,"0.00")&"s",TEXT(Data!L20,"0")&"s"),TEXT(Data!P20*100,"0")&"%") -> 40% | E8: =IF(Data!L33<3600,IF(Data!L33<120,TEXT(Data!L33,"0.00")&"s",TEXT(Data!L33,"0")&"s"),TEXT(Data!P33*100,"0")&"%") -> 40% | F8: =IF(Data!L46<3600,IF(Data!L46<120,TEXT(Data!L46,"0.00")&"s",TEXT(Data!L46,"0")&"s"),TEXT(Data!P46*100,"0")&"%") -> 39% | G8: =IF(Data!L59<3600,IF(Data!L59<120,TEXT(Data!L59,"0.00")&"s",TEXT(Data!L59,"0")&"s"),TEXT(Data!P59*100,"0")&"%") -> 35% | H8: =IF(Data!L72<3600,IF(Data!L72<120,TEXT(Data!L72,"0.00")&"s",TEXT(Data!L72,"0")&"s"),TEXT(Data!P72*100,"0")&"%") -> 34%
C9: =IF(Data!L8<3600,IF(Data!L8<120,TEXT(Data!L8,"0.00")&"s",TEXT(Data!L8,"0")&"s"),TEXT(Data!P8*100,"0")&"%") -> 51% | D9: =IF(Data!L21<3600,IF(Data!L21<120,TEXT(Data!L21,"0.00")&"s",TEXT(Data!L21,"0")&"s"),TEXT(Data!P21*100,"0")&"%") -> 51% | E9: =IF(Data!L34<3600,IF(Data!L34<120,TEXT(Data!L34,"0.00")&"s",TEXT(Data!L34,"0")&"s"),TEXT(Data!P34*100,"0")&"%") -> 53% | F9: =IF(Data!L47<3600,IF(Data!L47<120,TEXT(Data!L47,"0.00")&"s",TEXT(Data!L47,"0")&"s"),TEXT(Data!P47*100,"0")&"%") -> 52% | G9: =IF(Data!L60<3600,IF(Data!L60<120,TEXT(Data!L60,"0.00")&"s",TEXT(Data!L60,"0")&"s"),TEXT(Data!P60*100,"0")&"%") -> 49% | H9: =IF(Data!L73<3600,IF(Data!L73<120,TEXT(Data!L73,"0.00")&"s",TEXT(Data!L73,"0")&"s"),TEXT(Data!P73*100,"0")&"%") -> 48%
C10: =IF(Data!L9<3600,IF(Data!L9<120,TEXT(Data!L9,"0.00")&"s",TEXT(Data!L9,"0")&"s"),TEXT(Data!P9*100,"0")&"%") -> 51% | D10: =IF(Data!L22<3600,IF(Data!L22<120,TEXT(Data!L22,"0.00")&"s",TEXT(Data!L22,"0")&"s"),TEXT(Data!P22*100,"0")&"%") -> 52% | E10: =IF(Data!L35<3600,IF(Data!L35<120,TEXT(Data!L35,"0.00")&"s",TEXT(Data!L35,"0")&"s"),TEXT(Data!P35*100,"0")&"%") -> 53% | F10: =IF(Data!L48<3600,IF(Data!L48<120,TEXT(Data!L48,"0.00")&"s",TEXT(Data!L48,"0")&"s"),TEXT(Data!P48*100,"0")&"%") -> 52% | G10: =IF(Data!L61<3600,IF(Data!L61<120,TEXT(Data!L61,"0.00")&"s",TEXT(Data!L61,"0")&"s"),TEXT(Data!P61*100,"0")&"%") -> 51% | H10: =IF(Data!L74<3600,IF(Data!L74<120,TEXT(Data!L74,"0.00")&"s",TEXT(Data!L74,"0")&"s"),TEXT(Data!P74*100,"0")&"%") -> 51%
C11: =IF(Data!L10<3600,IF(Data!L10<120,TEXT(Data!L10,"0.00")&"s",TEXT(Data!L10,"0")&"s"),TEXT(Data!P10*100,"0")&"%") -> 48% | D11: =IF(Data!L23<3600,IF(Data!L23<120,TEXT(Data!L23,"0.00")&"s",TEXT(Data!L23,"0")&"s"),TEXT(Data!P23*100,"0")&"%") -> 48% | E11: =IF(Data!L36<3600,IF(Data!L36<120,TEXT(Data!L36,"0.00")&"s",TEXT(Data!L36,"0")&"s"),TEXT(Data!P36*100,"0")&"%") -> 52% | F11: =IF(Data!L49<3600,IF(Data!L49<120,TEXT(Data!L49,"0.00")&"s",TEXT(Data!L49,"0")&"s"),TEXT(Data!P49*100,"0")&"%") -> 51% | G11: =IF(Data!L62<3600,IF(Data!L62<120,TEXT(Data!L62,"0.00")&"s",TEXT(Data!L62,"0")&"s"),TEXT(Data!P62*100,"0")&"%") -> 49% | H11: =IF(Data!L75<3600,IF(Data!L75<120,TEXT(Data!L75,"0.00")&"s",TEXT(Data!L75,"0")&"s"),TEXT(Data!P75*100,"0")&"%") -> 49%
C12: =IF(Data!L11<3600,IF(Data!L11<120,TEXT(Data!L11,"0.00")&"s",TEXT(Data!L11,"0")&"s"),TEXT(Data!P11*100,"0")&"%") -> 48% | D12: =IF(Data!L24<3600,IF(Data!L24<120,TEXT(Data!L24,"0.00")&"s",TEXT(Data!L24,"0")&"s"),TEXT(Data!P24*100,"0")&"%") -> 48% | E12: =IF(Data!L37<3600,IF(Data!L37<120,TEXT(Data!L37,"0.00")&"s",TEXT(Data!L37,"0")&"s"),TEXT(Data!P37*100,"0")&"%") -> 51% | F12: =IF(Data!L50<3600,IF(Data!L50<120,TEXT(Data!L50,"0.00")&"s",TEXT(Data!L50,"0")&"s"),TEXT(Data!P50*100,"0")&"%") -> 52% | G12: =IF(Data!L63<3600,IF(Data!L63<120,TEXT(Data!L63,"0.00")&"s",TEXT(Data!L63,"0")&"s"),TEXT(Data!P63*100,"0")&"%") -> 49% | H12: =IF(Data!L76<3600,IF(Data!L76<120,TEXT(Data!L76,"0.00")&"s",TEXT(Data!L76,"0")&"s"),TEXT(Data!P76*100,"0")&"%") -> 48%
C13: =IF(Data!L12<3600,IF(Data!L12<120,TEXT(Data!L12,"0.00")&"s",TEXT(Data!L12,"0")&"s"),TEXT(Data!P12*100,"0")&"%") -> 81% | D13: =IF(Data!L25<3600,IF(Data!L25<120,TEXT(Data!L25,"0.00")&"s",TEXT(Data!L25,"0")&"s"),TEXT(Data!P25*100,"0")&"%") -> 82% | E13: =IF(Data!L38<3600,IF(Data!L38<120,TEXT(Data!L38,"0.00")&"s",TEXT(Data!L38,"0")&"s"),TEXT(Data!P38*100,"0")&"%") -> 82% | F13: =IF(Data!L51<3600,IF(Data!L51<120,TEXT(Data!L51,"0.00")&"s",TEXT(Data!L51,"0")&"s"),TEXT(Data!P51*100,"0")&"%") -> 82% | G13: =IF(Data!L64<3600,IF(Data!L64<120,TEXT(Data!L64,"0.00")&"s",TEXT(Data!L64,"0")&"s"),TEXT(Data!P64*100,"0")&"%") -> 69% | H13: =IF(Data!L77<3600,IF(Data!L77<120,TEXT(Data!L77,"0.00")&"s",TEXT(Data!L77,"0")&"s"),TEXT(Data!P77*100,"0")&"%") -> 69%
C14: =IF(Data!L13<3600,IF(Data!L13<120,TEXT(Data!L13,"0.00")&"s",TEXT(Data!L13,"0")&"s"),TEXT(Data!P13*100,"0")&"%") -> 72% | D14: =IF(Data!L26<3600,IF(Data!L26<120,TEXT(Data!L26,"0.00")&"s",TEXT(Data!L26,"0")&"s"),TEXT(Data!P26*100,"0")&"%") -> 74% | E14: =IF(Data!L39<3600,IF(Data!L39<120,TEXT(Data!L39,"0.00")&"s",TEXT(Data!L39,"0")&"s"),TEXT(Data!P39*100,"0")&"%") -> 77% | F14: =IF(Data!L52<3600,IF(Data!L52<120,TEXT(Data!L52,"0.00")&"s",TEXT(Data!L52,"0")&"s"),TEXT(Data!P52*100,"0")&"%") -> 77% | G14: =IF(Data!L65<3600,IF(Data!L65<120,TEXT(Data!L65,"0.00")&"s",TEXT(Data!L65,"0")&"s"),TEXT(Data!P65*100,"0")&"%") -> 77% | H14: =IF(Data!L78<3600,IF(Data!L78<120,TEXT(Data!L78,"0.00")&"s",TEXT(Data!L78,"0")&"s"),TEXT(Data!P78*100,"0")&"%") -> 77%
C16: Value
C17: =Data!N2 -> 39 | D17: =Data!N15 -> 39 | E17: =Data!N28 -> 39 | F17: =Data!N41 -> 39 | G17: =Data!N54 -> 39 | H17: =Data!N67 -> 39
C18: =Data!N3 -> 39 | D18: =Data!N16 -> 39 | E18: =Data!N29 -> 39 | F18: =Data!N42 -> 39 | G18: =Data!N55 -> 39 | H18: =Data!N68 -> 39
C19: =Data!N4 -> 45 | D19: =Data!N17 -> 45 | E19: =Data!N30 -> 45 | F19: =Data!N43 -> 45 | G19: =Data!N56 -> 45 | H19: =Data!N69 -> 45
C20: =Data!N5 -> 45 | D20: =Data!N18 -> 45 | E20: =Data!N31 -> 45 | F20: =Data!N44 -> 45 | G20: =Data!N57 -> 45 | H20: =Data!N70 -> 45
C21: =Data!N6 -> 76 | D21: =Data!N19 -> 78 | E21: =Data!N32 -> 78 | F21: =Data!N45 -> 78 | G21: =Data!N58 -> 77 | H21: =Data!N71 -> 78
C22: =Data!N7 -> 77 | D22: =Data!N20 -> 80 | E22: =Data!N33 -> 80 | F22: =Data!N46 -> 79 | G22: =Data!N59 -> 77 | H22: =Data!N72 -> 76
C23: =Data!N8 -> 70 | D23: =Data!N21 -> 69 | E23: =Data!N34 -> 72 | F23: =Data!N47 -> 71 | G23: =Data!N60 -> 70 | H23: =Data!N73 -> 69
C24: =Data!N9 -> 70 | D24: =Data!N22 -> 71 | E24: =Data!N35 -> 73 | F24: =Data!N48 -> 71 | G24: =Data!N61 -> 69 | H24: =Data!N74 -> 70
C25: =Data!N10 -> 93 | D25: =Data!N23 -> 93 | E25: =Data!N36 -> 101 | F25: =Data!N49 -> 98 | G25: =Data!N62 -> 94 | H25: =Data!N75 -> 94
C26: =Data!N11 -> 92 | D26: =Data!N24 -> 93 | E26: =Data!N37 -> 97 | F26: =Data!N50 -> 99 | G26: =Data!N63 -> 94 | H26: =Data!N76 -> 92
C27: =Data!N12 -> 180 | D27: =Data!N25 -> 191 | E27: =Data!N38 -> 191.6 | F27: =Data!N51 -> 191.6 | G27: =Data!N64 -> 157 | H27: =Data!N77 -> 155
C28: =Data!N13 -> 145 | D28: =Data!N26 -> 153 | E28: =Data!N39 -> 171 | F28: =Data!N52 -> 171 | G28: =Data!N65 -> 153 | H28: =Data!N78 -> 150
C30: Bound
C31: =Data!O2 -> 39 | D31: =Data!O15 -> 39 | E31: =Data!O28 -> 39 | F31: =Data!O41 -> 39 | G31: =Data!O54 -> 39 | H31: =Data!O67 -> 39
C32: =Data!O3 -> 39 | D32: =Data!O16 -> 39 | E32: =Data!O29 -> 39 | F32: =Data!O42 -> 39 | G32: =Data!O55 -> 39 | H32: =Data!O68 -> 39
C33: =Data!O4 -> 45 | D33: =Data!O17 -> 45 | E33: =Data!O30 -> 45 | F33: =Data!O43 -> 45 | G33: =Data!O56 -> 45 | H33: =Data!O69 -> 45
C34: =Data!O5 -> 45 | D34: =Data!O18 -> 45 | E34: =Data!O31 -> 45 | F34: =Data!O44 -> 45 | G34: =Data!O57 -> 45 | H34: =Data!O70 -> 45
C35: =Data!O6 -> 50 | D35: =Data!O19 -> 50 | E35: =Data!O32 -> 48 | F35: =Data!O45 -> 46 | G35: =Data!O58 -> 53 | H35: =Data!O71 -> 53
C36: =Data!O7 -> 48 | D36: =Data!O20 -> 48 | E36: =Data!O33 -> 48 | F36: =Data!O46 -> 48 | G36: =Data!O59 -> 50 | H36: =Data!O72 -> 50
C37: =Data!O8 -> 34 | D37: =Data!O21 -> 34 | E37: =Data!O34 -> 34 | F37: =Data!O47 -> 34 | G37: =Data!O60 -> 36 | H37: =Data!O73 -> 36
C38: =Data!O9 -> 34 | D38: =Data!O22 -> 34 | E38: =Data!O35 -> 34 | F38: =Data!O48 -> 34 | G38: =Data!O61 -> 34 | H38: =Data!O74 -> 34
C39: =Data!O10 -> 48 | D39: =Data!O23 -> 48 | E39: =Data!O36 -> 48 | F39: =Data!O49 -> 48 | G39: =Data!O62 -> 48 | H39: =Data!O75 -> 48
C40: =Data!O11 -> 48 | D40: =Data!O24 -> 48 | E40: =Data!O37 -> 48 | F40: =Data!O50 -> 48 | G40: =Data!O63 -> 48 | H40: =Data!O76 -> 48
C41: =Data!O12 -> 35 | D41: =Data!O25 -> 35 | E41: =Data!O38 -> 35 | F41: =Data!O51 -> 35 | G41: =Data!O64 -> 48 | H41: =Data!O77 -> 48
C42: =Data!O13 -> 40 | D42: =Data!O26 -> 40 | E42: =Data!O39 -> 40 | F42: =Data!O52 -> 40 | G42: =Data!O65 -> 35 | H42: =Data!O78 -> 35
...
